<?xml version="1.0" ?>
<!-- =================================================================================== -->
<!-- |    This document was autogenerated by xacro from irb6640_185_280.xacro          | -->
<!-- |    EDITING THIS FILE BY HAND IS NOT RECOMMENDED                                 | -->
<!-- =================================================================================== -->
<robot name="abb_irb6640_185_280">
    <!-- world link -->
    <!-- <link name="world"/> -->
    <!-- Track link -->
    <link name="track">
        <collision name="collision">
            <geometry>
                <mesh filename="package://abb_irb6640_support/meshes/irb6640_185_280/collision/abb_irb6640_track.stl" />
            </geometry>
        </collision>
        <visual name="visual">
            <geometry>
                <mesh filename="package://abb_irb6640_support/meshes/irb6640_185_280/visual/abb_irb6640_track.stl" />
            </geometry>
            <material name="yellow">
                <color rgba="1 1 0 1" />
            </material>
        </visual>
        <inertial>
            <mass value="0.1" />
            <origin xyz="0 0 0" rpy="0 0 0" />
            <inertia ixx="0.03" iyy="0.03" izz="0.03" ixy="0.0" ixz="0.0" iyz="0.0" />
        </inertial>
    </link>
    <!-- track loader link-->
    <link name="track_loader">
        <collision name="collision">
            <geometry>
                <mesh filename="package://abb_irb6640_support/meshes/irb6640_185_280/collision/abb_irb6640_link1_track_loader.stl" />
            </geometry>
        </collision>
        <visual name="visual">
            <geometry>
                <mesh filename="package://abb_irb6640_support/meshes/irb6640_185_280/visual/abb_irb6640_link1_track_loader.stl" />
            </geometry>
            <material name="yellow">
                <color rgba="1 1 0 1" />
            </material>
        </visual>
        <inertial>
            <mass value="0.1" />
            <origin xyz="0 0 0" rpy="0 0 0" />
            <inertia ixx="0.03" iyy="0.03" izz="0.03" ixy="0.0" ixz="0.0" iyz="0.0" />
        </inertial>
    </link>
    <!-- IRB6640 link list -->
    <link name="base_link">
        <collision name="collision">
            <geometry>
                <mesh filename="package://abb_irb6640_support/meshes/irb6640_185_280/collision/base_link.stl" />
            </geometry>
        </collision>
        <visual name="visual">
            <geometry>
                <mesh filename="package://abb_irb6640_support/meshes/irb6640_185_280/visual/base_link.dae" />
            </geometry>
            <material name="yellow">
                <color rgba="1 1 0 1" />
            </material>
        </visual>
        <inertial>
            <mass value="0.1" />
            <origin xyz="0 0 0" rpy="0 0 0" />
            <inertia ixx="0.03" iyy="0.03" izz="0.03" ixy="0.0" ixz="0.0" iyz="0.0" />
        </inertial>
    </link>
    <link name="link_1">
        <collision name="collision">
            <geometry>
                <mesh filename="package://abb_irb6640_support/meshes/irb6640_185_280/collision/link_1.stl" />
            </geometry>
        </collision>
        <visual name="visual">
            <geometry>
                <mesh filename="package://abb_irb6640_support/meshes/irb6640_185_280/visual/link_1.dae" />
            </geometry>
            <material name="yellow" />
        </visual>
        <inertial>
            <mass value="0.1" />
            <origin xyz="0 0 0" rpy="0 0 0" />
            <inertia ixx="0.03" iyy="0.03" izz="0.03" ixy="0.0" ixz="0.0" iyz="0.0" />
        </inertial>
    </link>
    <link name="link_2">
        <collision name="collision">
            <geometry>
                <mesh filename="package://abb_irb6640_support/meshes/irb6640_185_280/collision/link_2.stl" />
            </geometry>
        </collision>
        <visual name="visual">
            <geometry>
                <mesh filename="package://abb_irb6640_support/meshes/irb6640_185_280/visual/link_2.dae" />
            </geometry>
            <material name="yellow" />
        </visual>
        <inertial>
            <mass value="0.1" />
            <origin xyz="0 0 0" rpy="0 0 0" />
            <inertia ixx="0.03" iyy="0.03" izz="0.03" ixy="0.0" ixz="0.0" iyz="0.0" />
        </inertial>
    </link>
    <link name="link_3">
        <collision name="collision">
            <geometry>
                <mesh filename="package://abb_irb6640_support/meshes/irb6640_185_280/collision/link_3.stl" />
            </geometry>
        </collision>
        <visual name="visual">
            <geometry>
                <mesh filename="package://abb_irb6640_support/meshes/irb6640_185_280/visual/link_3.dae" />
            </geometry>
            <material name="yellow" />
        </visual>
        <inertial>
            <mass value="0.1" />
            <origin xyz="0 0 0" rpy="0 0 0" />
            <inertia ixx="0.03" iyy="0.03" izz="0.03" ixy="0.0" ixz="0.0" iyz="0.0" />
        </inertial>
    </link>
    <link name="link_4">
        <collision name="collision">
            <geometry>
                <mesh filename="package://abb_irb6640_support/meshes/irb6640_185_280/collision/link_4.stl" />
            </geometry>
        </collision>
        <visual name="visual">
            <geometry>
                <mesh filename="package://abb_irb6640_support/meshes/irb6640_185_280/visual/link_4.dae" />
            </geometry>
            <material name="yellow" />
        </visual>
        <inertial>
            <mass value="0.1" />
            <origin xyz="0 0 0" rpy="0 0 0" />
            <inertia ixx="0.03" iyy="0.03" izz="0.03" ixy="0.0" ixz="0.0" iyz="0.0" />
        </inertial>
    </link>
    <link name="link_5">
        <collision name="collision">
            <geometry>
                <mesh filename="package://abb_irb6640_support/meshes/irb6640_185_280/collision/link_5.stl" />
            </geometry>
        </collision>
        <visual name="visual">
            <geometry>
                <mesh filename="package://abb_irb6640_support/meshes/irb6640_185_280/visual/link_5.dae" />
            </geometry>
            <material name="yellow" />
        </visual>
        <inertial>
            <mass value="0.1" />
            <origin xyz="0 0 0" rpy="0 0 0" />
            <inertia ixx="0.03" iyy="0.03" izz="0.03" ixy="0.0" ixz="0.0" iyz="0.0" />
        </inertial>
    </link>
    <link name="link_6">
        <collision name="collision">
            <geometry>
                <mesh filename="package://abb_irb6640_support/meshes/irb6640_185_280/collision/link_6.stl" />
            </geometry>
        </collision>
        <visual name="visual">
            <geometry>
                <mesh filename="package://abb_irb6640_support/meshes/irb6640_185_280/visual/link_6.dae" />
            </geometry>
            <material name="yellow" />
        </visual>
        <inertial>
            <mass value="0.1" />
            <origin xyz="0 0 0" rpy="0 0 0" />
            <inertia ixx="0.03" iyy="0.03" izz="0.03" ixy="0.0" ixz="0.0" iyz="0.0" />
        </inertial>
    </link>
    <link name="tool0" />
    <!--Cylinder and piston -->
    <link name="link_cylinder">
        <collision name="collision">
            <geometry>
                <mesh filename="package://abb_irb6640_support/meshes/irb6640_185_280/collision/cylinder_link.stl" />
            </geometry>
        </collision>
        <visual name="visual">
            <geometry>
                <mesh filename="package://abb_irb6640_support/meshes/irb6640_185_280/visual/cylinder_link.dae" />
            </geometry>
            <material name="yellow" />
        </visual>
        <inertial>
            <mass value="0.1" />
            <origin xyz="0 0 0" rpy="0 0 0" />
            <inertia ixx="0.03" iyy="0.03" izz="0.03" ixy="0.0" ixz="0.0" iyz="0.0" />
        </inertial>
    </link>
    <link name="link_piston">
        <collision name="collision">
            <geometry>
                <mesh filename="package://abb_irb6640_support/meshes/irb6640_185_280/collision/piston_link.stl" />
            </geometry>
        </collision>
        <visual name="visual">
            <geometry>
                <mesh filename="package://abb_irb6640_support/meshes/irb6640_185_280/visual/piston_link.dae" />
            </geometry>
            <material name="yellow" />
        </visual>
        <inertial>
            <mass value="0.1" />
            <origin xyz="0 0 0" rpy="0 0 0" />
            <inertia ixx="0.03" iyy="0.03" izz="0.03" ixy="0.0" ixz="0.0" iyz="0.0" />
        </inertial>
    </link>
    <!-- end of link list -->
    <!-- Track joint list -->
    <!-- end of track joint list -->
    <!-- <joint name="track_link1" type="fixed">
    <origin rpy="0 0 0" xyz="4 0 0"/>
    <axis xyz="0 0 0"/>
    <parent link="Track_link1"/>
    <child link="base_link"/>
    <limit effort="0" lower="0" upper="3" velocity="1"/>
  </joint> -->
    <!-- IRB6640 joint list -->
    <joint name="joint_1" type="revolute">
        <origin rpy="0 0 0" xyz="0 0 0.780" />
        <axis xyz="0 0 1" />
        <parent link="base_link" />
        <child link="link_1" />
        <limit effort="0" lower="-2.967" upper="2.967" velocity="1.7453" />
    </joint>
    <joint name="joint_2" type="revolute">
        <origin rpy="0 0 0" xyz="0.320 0 0" />
        <axis xyz="0 1 0" />
        <parent link="link_1" />
        <child link="link_2" />
        <limit effort="0" lower="-1.134" upper="1.4855" velocity="1.5707" />
    </joint>
    <joint name="joint_3" type="revolute">
        <origin rpy="0 0 0" xyz="0 0 1.075" />
        <axis xyz="0 1 0" />
        <parent link="link_2" />
        <child link="link_3" />
        <limit effort="0" lower="-3.142" upper="1.222" velocity="1.5707" />
    </joint>
    <joint name="joint_4" type="revolute">
        <origin rpy="0 0 0" xyz="0 0 0.2" />
        <axis xyz="1 0 0" />
        <parent link="link_3" />
        <child link="link_4" />
        <limit effort="0" lower="-5.236" upper="5.236" velocity="2.9671" />
    </joint>
    <joint name="joint_5" type="revolute">
        <origin rpy="0 0 0" xyz="1.392 0 0 " />
        <axis xyz="0 1 0" />
        <parent link="link_4" />
        <child link="link_5" />
        <limit effort="0" lower="-2.094" upper="2.094" velocity="2.4435" />
    </joint>
    <joint name="joint_6" type="revolute">
        <origin rpy="0 0 0" xyz="0.2 0 0 " />
        <axis xyz="1 0 0" />
        <parent link="link_5" />
        <child link="link_6" />
        <limit effort="0" lower="-6.283" upper="6.283" velocity="3.3161" />
    </joint>
    <joint name="joint_6-tool0" type="fixed">
        <parent link="link_6" />
        <child link="tool0" />
        <origin rpy="0 1.57079632679 0" xyz="0 0 0" />
    </joint>
    <joint name="joint_cylinder" type="continuous">
        <origin rpy="0 0 0" xyz="-0.3647 0 -0.1455" />
        <axis xyz="0 1 0" />
        <parent link="link_1" />
        <child link="link_cylinder" />
        <mimic joint="joint_2" multiplier="-0.25" />
    </joint>
    <joint name="joint_piston" type="continuous">
        <origin rpy="0 0 0" xyz="-0.22 0 -0.0672" />
        <axis xyz="0 1 0" />
        <parent link="link_2" />
        <child link="link_piston" />
        <mimic joint="joint_2" multiplier="-1.25" />
    </joint>
    <!-- end of IRB6640 joint list -->
    <!-- ROS base_link to ABB World Coordinates transform -->
    <!-- <joint name="base_track" type="fixed">
    <origin rpy="0 0 0" xyz="0 0 0"/>
    <parent link="world"/>
    <child link="track"/>
  </joint> -->
    <joint name="track1" type="prismatic">
        <parent link="track" />
        <child link="track_loader" />
        <origin xyz="0 0 0" rpy="0 0 0" />
        <axis xyz="1 0 0" />
        <!-- Movement along the x-axis -->
        <limit lower="0.0" upper="4.0" effort="100" velocity="1.0" />
    </joint>
    <joint name="loader_base" type="fixed">
        <origin rpy="0 0 0" xyz="0 0 0" />
        <parent link="track_loader" />
        <child link="base_link" />
    </joint>
    <transmission name="trans_joint_1">
        <type>transmission_interface/SimpleTransmission</type>
        <joint name="joint_1">
            <hardwareInterface>hardware_interface/EffortJointInterface</hardwareInterface>
        </joint>
        <actuator name="joint_1_motor">
            <hardwareInterface>hardware_interface/EffortJointInterface</hardwareInterface>
            <mechanicalReduction>1</mechanicalReduction>
        </actuator>
    </transmission>
    <transmission name="trans_joint_2">
        <type>transmission_interface/SimpleTransmission</type>
        <joint name="joint_2">
            <hardwareInterface>hardware_interface/EffortJointInterface</hardwareInterface>
        </joint>
        <actuator name="joint_2_motor">
            <hardwareInterface>hardware_interface/EffortJointInterface</hardwareInterface>
            <mechanicalReduction>1</mechanicalReduction>
        </actuator>
    </transmission>
    <transmission name="trans_joint_3">
        <type>transmission_interface/SimpleTransmission</type>
        <joint name="joint_3">
            <hardwareInterface>hardware_interface/EffortJointInterface</hardwareInterface>
        </joint>
        <actuator name="joint_3_motor">
            <hardwareInterface>hardware_interface/EffortJointInterface</hardwareInterface>
            <mechanicalReduction>1</mechanicalReduction>
        </actuator>
    </transmission>
    <transmission name="trans_joint_4">
        <type>transmission_interface/SimpleTransmission</type>
        <joint name="joint_4">
            <hardwareInterface>hardware_interface/EffortJointInterface</hardwareInterface>
        </joint>
        <actuator name="joint_4_motor">
            <hardwareInterface>hardware_interface/EffortJointInterface</hardwareInterface>
            <mechanicalReduction>1</mechanicalReduction>
        </actuator>
    </transmission>
    <transmission name="trans_joint_5">
        <type>transmission_interface/SimpleTransmission</type>
        <joint name="joint_5">
            <hardwareInterface>hardware_interface/EffortJointInterface</hardwareInterface>
        </joint>
        <actuator name="joint_5_motor">
            <hardwareInterface>hardware_interface/EffortJointInterface</hardwareInterface>
            <mechanicalReduction>1</mechanicalReduction>
        </actuator>
    </transmission>
    <transmission name="trans_joint_6">
        <type>transmission_interface/SimpleTransmission</type>
        <joint name="joint_6">
            <hardwareInterface>hardware_interface/EffortJointInterface</hardwareInterface>
        </joint>
        <actuator name="joint_6_motor">
            <hardwareInterface>hardware_interface/EffortJointInterface</hardwareInterface>
            <mechanicalReduction>1</mechanicalReduction>
        </actuator>
    </transmission>
    <transmission name="trans_joint_cylinder">
        <type>transmission_interface/SimpleTransmission</type>
        <joint name="joint_cylinder">
            <hardwareInterface>hardware_interface/EffortJointInterface</hardwareInterface>
        </joint>
        <actuator name="joint_cylinder_motor">
            <hardwareInterface>hardware_interface/EffortJointInterface</hardwareInterface>
            <mechanicalReduction>1</mechanicalReduction>
        </actuator>
    </transmission>
    <transmission name="trans_joint_piston">
        <type>transmission_interface/SimpleTransmission</type>
        <joint name="joint_piston">
            <hardwareInterface>hardware_interface/EffortJointInterface</hardwareInterface>
        </joint>
        <actuator name="joint_piston_motor">
            <hardwareInterface>hardware_interface/EffortJointInterface</hardwareInterface>
            <mechanicalReduction>1</mechanicalReduction>
        </actuator>
    </transmission>
    <transmission name="trans_track1">
        <type>transmission_interface/SimpleTransmission</type>
        <joint name="track1">
            <hardwareInterface>hardware_interface/EffortJointInterface</hardwareInterface>
        </joint>
        <actuator name="track1_motor">
            <hardwareInterface>hardware_interface/EffortJointInterface</hardwareInterface>
            <mechanicalReduction>1</mechanicalReduction>
        </actuator>
    </transmission>
    <gazebo>
        <plugin name="gazebo_ros_control">
            <robotNamespace>/</robotNamespace>
        </plugin>
    </gazebo>
</robot>

