<?xml version="1.0" ?>
<!-- =================================================================================== -->
<!-- |    This document was autogenerated by xacro from /home/vina/catkin_ws/src/abb_irb6640_irb4400_dfab_support/urdf/irb6640_irb4400.xacro | -->
<!-- |    EDITING THIS FILE BY HAND IS NOT RECOMMENDED                                 | -->
<!-- =================================================================================== -->
<robot name="irb6640_irb4400_dfab">
    <!-- Track link list -->
    <!-- <link name="${prefix}world"/> -->
    <!-- Track link -->
    <link name="irb6640_track">
        <collision name="collision">
            <geometry>
                <mesh filename="package://abb_irb6640_support/meshes/irb6640_185_280/collision/abb_irb6640_track.stl" />
            </geometry>
        </collision>
        <visual name="visual">
            <geometry>
                <mesh filename="package://abb_irb6640_support/meshes/irb6640_185_280/visual/abb_irb6640_track.stl" />
            </geometry>
            <material name="yellow">
                <color rgba="1 1 0 1" />
            </material>
        </visual>
        <inertial>
            <mass value="0.1" />
            <origin xyz="0 0 0" rpy="0 0 0" />
            <inertia ixx="0.03" iyy="0.03" izz="0.03" ixy="0.0" ixz="0.0" iyz="0.0" />
        </inertial>
    </link>
    <!-- track loader link-->
    <link name="irb6640_track_loader">
        <collision name="collision">
            <geometry>
                <mesh filename="package://abb_irb6640_support/meshes/irb6640_185_280/collision/abb_irb6640_link1_track_loader.stl" />
            </geometry>
        </collision>
        <visual name="visual">
            <geometry>
                <mesh filename="package://abb_irb6640_support/meshes/irb6640_185_280/visual/abb_irb6640_link1_track_loader.stl" />
            </geometry>
            <material name="yellow">
                <color rgba="1 1 0 1" />
            </material>
        </visual>
        <inertial>
            <mass value="0.1" />
            <origin xyz="0 0 0" rpy="0 0 0" />
            <inertia ixx="0.03" iyy="0.03" izz="0.03" ixy="0.0" ixz="0.0" iyz="0.0" />
        </inertial>
    </link>
    <!-- IRB6640 link list -->
    <link name="irb6640_base_link">
        <collision name="collision">
            <geometry>
                <mesh filename="package://abb_irb6640_support/meshes/irb6640_185_280/collision/base_link.stl" />
            </geometry>
        </collision>
        <visual name="visual">
            <geometry>
                <mesh filename="package://abb_irb6640_support/meshes/irb6640_185_280/visual/base_link.dae" />
            </geometry>
            <material name="yellow">
                <color rgba="1 1 0 1" />
            </material>
        </visual>
        <inertial>
            <mass value="0.1" />
            <origin xyz="0 0 0" rpy="0 0 0" />
            <inertia ixx="0.03" iyy="0.03" izz="0.03" ixy="0.0" ixz="0.0" iyz="0.0" />
        </inertial>
    </link>
    <link name="irb6640_link_1">
        <collision name="collision">
            <geometry>
                <mesh filename="package://abb_irb6640_support/meshes/irb6640_185_280/collision/link_1.stl" />
            </geometry>
        </collision>
        <visual name="visual">
            <geometry>
                <mesh filename="package://abb_irb6640_support/meshes/irb6640_185_280/visual/link_1.dae" />
            </geometry>
            <material name="yellow" />
        </visual>
        <inertial>
            <mass value="0.1" />
            <origin xyz="0 0 0" rpy="0 0 0" />
            <inertia ixx="0.03" iyy="0.03" izz="0.03" ixy="0.0" ixz="0.0" iyz="0.0" />
        </inertial>
    </link>
    <link name="irb6640_link_2">
        <collision name="collision">
            <geometry>
                <mesh filename="package://abb_irb6640_support/meshes/irb6640_185_280/collision/link_2.stl" />
            </geometry>
        </collision>
        <visual name="visual">
            <geometry>
                <mesh filename="package://abb_irb6640_support/meshes/irb6640_185_280/visual/link_2.dae" />
            </geometry>
            <material name="yellow" />
        </visual>
        <inertial>
            <mass value="0.1" />
            <origin xyz="0 0 0" rpy="0 0 0" />
            <inertia ixx="0.03" iyy="0.03" izz="0.03" ixy="0.0" ixz="0.0" iyz="0.0" />
        </inertial>
    </link>
    <link name="irb6640_link_3">
        <collision name="collision">
            <geometry>
                <mesh filename="package://abb_irb6640_support/meshes/irb6640_185_280/collision/link_3.stl" />
            </geometry>
        </collision>
        <visual name="visual">
            <geometry>
                <mesh filename="package://abb_irb6640_support/meshes/irb6640_185_280/visual/link_3.dae" />
            </geometry>
            <material name="yellow" />
        </visual>
        <inertial>
            <mass value="0.1" />
            <origin xyz="0 0 0" rpy="0 0 0" />
            <inertia ixx="0.03" iyy="0.03" izz="0.03" ixy="0.0" ixz="0.0" iyz="0.0" />
        </inertial>
    </link>
    <link name="irb6640_link_4">
        <collision name="collision">
            <geometry>
                <mesh filename="package://abb_irb6640_support/meshes/irb6640_185_280/collision/link_4.stl" />
            </geometry>
        </collision>
        <visual name="visual">
            <geometry>
                <mesh filename="package://abb_irb6640_support/meshes/irb6640_185_280/visual/link_4.dae" />
            </geometry>
            <material name="yellow" />
        </visual>
        <inertial>
            <mass value="0.1" />
            <origin xyz="0 0 0" rpy="0 0 0" />
            <inertia ixx="0.03" iyy="0.03" izz="0.03" ixy="0.0" ixz="0.0" iyz="0.0" />
        </inertial>
    </link>
    <link name="irb6640_link_5">
        <collision name="collision">
            <geometry>
                <mesh filename="package://abb_irb6640_support/meshes/irb6640_185_280/collision/link_5.stl" />
            </geometry>
        </collision>
        <visual name="visual">
            <geometry>
                <mesh filename="package://abb_irb6640_support/meshes/irb6640_185_280/visual/link_5.dae" />
            </geometry>
            <material name="yellow" />
        </visual>
        <inertial>
            <mass value="0.1" />
            <origin xyz="0 0 0" rpy="0 0 0" />
            <inertia ixx="0.03" iyy="0.03" izz="0.03" ixy="0.0" ixz="0.0" iyz="0.0" />
        </inertial>
    </link>
    <link name="irb6640_link_6">
        <collision name="collision">
            <geometry>
                <mesh filename="package://abb_irb6640_support/meshes/irb6640_185_280/collision/link_6.stl" />
            </geometry>
        </collision>
        <visual name="visual">
            <geometry>
                <mesh filename="package://abb_irb6640_support/meshes/irb6640_185_280/visual/link_6.dae" />
            </geometry>
            <material name="yellow" />
        </visual>
        <inertial>
            <mass value="0.1" />
            <origin xyz="0 0 0" rpy="0 0 0" />
            <inertia ixx="0.03" iyy="0.03" izz="0.03" ixy="0.0" ixz="0.0" iyz="0.0" />
        </inertial>
    </link>
    <link name="irb6640_tool0" />
    <!--Cylinder and piston -->
    <link name="irb6640_link_cylinder">
        <collision name="collision">
            <geometry>
                <mesh filename="package://abb_irb6640_support/meshes/irb6640_185_280/collision/cylinder_link.stl" />
            </geometry>
        </collision>
        <visual name="visual">
            <geometry>
                <mesh filename="package://abb_irb6640_support/meshes/irb6640_185_280/visual/cylinder_link.dae" />
            </geometry>
            <material name="yellow" />
        </visual>
        <inertial>
            <mass value="0.1" />
            <origin xyz="0 0 0" rpy="0 0 0" />
            <inertia ixx="0.03" iyy="0.03" izz="0.03" ixy="0.0" ixz="0.0" iyz="0.0" />
        </inertial>
    </link>
    <link name="irb6640_link_piston">
        <collision name="collision">
            <geometry>
                <mesh filename="package://abb_irb6640_support/meshes/irb6640_185_280/collision/piston_link.stl" />
            </geometry>
        </collision>
        <visual name="visual">
            <geometry>
                <mesh filename="package://abb_irb6640_support/meshes/irb6640_185_280/visual/piston_link.dae" />
            </geometry>
            <material name="yellow" />
        </visual>
        <inertial>
            <mass value="0.1" />
            <origin xyz="0 0 0" rpy="0 0 0" />
            <inertia ixx="0.03" iyy="0.03" izz="0.03" ixy="0.0" ixz="0.0" iyz="0.0" />
        </inertial>
    </link>
    <!-- end of link list -->
    <!-- Track joint list -->
    <!-- end of track joint list -->
    <!-- IRB6640 joint list -->
    <joint name="irb6640_joint_1" type="revolute">
        <origin rpy="0 0 0" xyz="0 0 0.780" />
        <axis xyz="0 0 1" />
        <parent link="irb6640_base_link" />
        <child link="irb6640_link_1" />
        <limit effort="0" lower="-2.967" upper="2.967" velocity="1.7453" />
    </joint>
    <joint name="irb6640_joint_2" type="revolute">
        <origin rpy="0 0 0" xyz="0.320 0 0" />
        <axis xyz="0 1 0" />
        <parent link="irb6640_link_1" />
        <child link="irb6640_link_2" />
        <limit effort="0" lower="-1.134" upper="1.4855" velocity="1.5707" />
    </joint>
    <joint name="irb6640_joint_3" type="revolute">
        <origin rpy="0 0 0" xyz="0 0 1.075" />
        <axis xyz="0 1 0" />
        <parent link="irb6640_link_2" />
        <child link="irb6640_link_3" />
        <limit effort="0" lower="-3.142" upper="1.222" velocity="1.5707" />
    </joint>
    <joint name="irb6640_joint_4" type="revolute">
        <origin rpy="0 0 0" xyz="0 0 0.2" />
        <axis xyz="1 0 0" />
        <parent link="irb6640_link_3" />
        <child link="irb6640_link_4" />
        <limit effort="0" lower="-5.236" upper="5.236" velocity="2.9671" />
    </joint>
    <joint name="irb6640_joint_5" type="revolute">
        <origin rpy="0 0 0" xyz="1.392 0 0 " />
        <axis xyz="0 1 0" />
        <parent link="irb6640_link_4" />
        <child link="irb6640_link_5" />
        <limit effort="0" lower="-2.094" upper="2.094" velocity="2.4435" />
    </joint>
    <joint name="irb6640_joint_6" type="revolute">
        <origin rpy="0 0 0" xyz="0.2 0 0 " />
        <axis xyz="1 0 0" />
        <parent link="irb6640_link_5" />
        <child link="irb6640_link_6" />
        <limit effort="0" lower="-6.283" upper="6.283" velocity="3.3161" />
    </joint>
    <joint name="irb6640_joint_6-tool0" type="fixed">
        <parent link="irb6640_link_6" />
        <child link="irb6640_tool0" />
        <origin rpy="0 1.57079632679 0" xyz="0 0 0" />
    </joint>
    <joint name="irb6640_joint_cylinder" type="continuous">
        <origin rpy="0 0 0" xyz="-0.3647 0 -0.1455" />
        <axis xyz="0 1 0" />
        <parent link="irb6640_link_1" />
        <child link="irb6640_link_cylinder" />
        <mimic joint="irb6640_joint_2" multiplier="-0.25" />
    </joint>
    <joint name="irb6640_joint_piston" type="continuous">
        <origin rpy="0 0 0" xyz="-0.22 0 -0.0672" />
        <axis xyz="0 1 0" />
        <parent link="irb6640_link_2" />
        <child link="irb6640_link_piston" />
        <mimic joint="irb6640_joint_2" multiplier="-1.25" />
    </joint>
    <!-- end of IRB6640 joint list -->
    <!-- ROS base_link to ABB World Coordinates transform -->
    <!-- <joint name="${prefix}base_track" type="fixed">
      <origin rpy="0 0 0" xyz="0 0 0"/>
      <parent link="${prefix}world"/>
      <child link="${prefix}track"/>
    </joint> -->
    <joint name="irb6640_track_1" type="prismatic">
        <parent link="irb6640_track" />
        <child link="irb6640_track_loader" />
        <origin rpy="0 0 0" xyz="0 0 0" />
        <axis xyz="1 0 0" />
        <!-- Movement along the x-axis -->
        <limit effort="100" lower="0.0" upper="5.69" velocity="1.0" />
    </joint>
    <joint name="irb6640_loader_base" type="fixed">
        <origin rpy="0 0 0" xyz="0 0 0" />
        <parent link="irb6640_track_loader" />
        <child link="irb6640_base_link" />
    </joint>
    <!-- Conversion were obtained from http://www.e-paint.co.uk/Lab_values.asp
       unless otherwise stated. -->
    <!-- link list -->
    <link name="irb4400_base_link">
        <visual>
            <origin rpy="0 0 0" xyz="0 0 0" />
            <geometry>
                <mesh filename="package://abb_irb4400_45_support/meshes/irb4400_45_196/visual/base_link.stl" />
            </geometry>
            <material name="">
                <color rgba="0.7372549 0.3490196 0.1607843 1" />
            </material>
        </visual>
        <collision>
            <geometry>
                <mesh filename="package://abb_irb4400_45_support/meshes/irb4400_45_196/collision/base_link.stl" />
            </geometry>
            <material name="">
                <color rgba="1 1 0 1" />
            </material>
        </collision>
        <inertial>
            <mass value="0.1" />
            <origin xyz="0 0 0" rpy="0 0 0" />
            <inertia ixx="0.03" iyy="0.03" izz="0.03" ixy="0.0" ixz="0.0" iyz="0.0" />
        </inertial>
    </link>
    <link name="irb4400_link_1">
        <visual>
            <origin rpy="0 0 0" xyz="0 0 0" />
            <geometry>
                <mesh filename="package://abb_irb4400_45_support/meshes/irb4400_45_196/visual/link_1.stl" />
            </geometry>
            <material name="">
                <color rgba="0.7372549 0.3490196 0.1607843 1" />
            </material>
        </visual>
        <collision>
            <origin rpy="0 0 0" xyz="0 0 0" />
            <geometry>
                <mesh filename="package://abb_irb4400_45_support/meshes/irb4400_45_196/collision/link_1.stl" />
            </geometry>
            <material name="">
                <color rgba="1 1 0 1" />
            </material>
        </collision>
        <inertial>
            <mass value="0.1" />
            <origin xyz="0 0 0" rpy="0 0 0" />
            <inertia ixx="0.03" iyy="0.03" izz="0.03" ixy="0.0" ixz="0.0" iyz="0.0" />
        </inertial>
    </link>
    <link name="irb4400_link_2">
        <visual>
            <origin rpy="0 0 0" xyz="0 0 0" />
            <geometry>
                <mesh filename="package://abb_irb4400_45_support/meshes/irb4400_45_196/visual/link_2.stl" />
            </geometry>
            <material name="">
                <color rgba="0.7372549 0.3490196 0.1607843 1" />
            </material>
        </visual>
        <collision>
            <origin rpy="0 0 0" xyz="0 0 0" />
            <geometry>
                <mesh filename="package://abb_irb4400_45_support/meshes/irb4400_45_196/collision/link_2.stl" />
            </geometry>
            <material name="">
                <color rgba="1 1 0 1" />
            </material>
        </collision>
        <inertial>
            <mass value="0.1" />
            <origin xyz="0 0 0" rpy="0 0 0" />
            <inertia ixx="0.03" iyy="0.03" izz="0.03" ixy="0.0" ixz="0.0" iyz="0.0" />
        </inertial>
    </link>
    <link name="irb4400_link_3">
        <visual>
            <origin rpy="0 0 0" xyz="0 0 0" />
            <geometry>
                <mesh filename="package://abb_irb4400_45_support/meshes/irb4400_45_196/visual/link_3.stl" />
            </geometry>
            <material name="">
                <color rgba="0.7372549 0.3490196 0.1607843 1" />
            </material>
        </visual>
        <collision>
            <origin rpy="0 0 0" xyz="0 0 0" />
            <geometry>
                <mesh filename="package://abb_irb4400_45_support/meshes/irb4400_45_196/collision/link_3.stl" />
            </geometry>
            <material name="">
                <color rgba="1 1 0 1" />
            </material>
        </collision>
        <inertial>
            <mass value="0.1" />
            <origin xyz="0 0 0" rpy="0 0 0" />
            <inertia ixx="0.03" iyy="0.03" izz="0.03" ixy="0.0" ixz="0.0" iyz="0.0" />
        </inertial>
    </link>
    <link name="irb4400_link_4">
        <visual>
            <origin rpy="0 0 0" xyz="0 0 0" />
            <geometry>
                <mesh filename="package://abb_irb4400_45_support/meshes/irb4400_45_196/visual/link_4.stl" />
            </geometry>
            <material name="">
                <color rgba="0.7372549 0.3490196 0.1607843 1" />
            </material>
        </visual>
        <collision>
            <origin rpy="0 0 0" xyz="0 0 0" />
            <geometry>
                <mesh filename="package://abb_irb4400_45_support/meshes/irb4400_45_196/collision/link_4.stl" />
            </geometry>
            <material name="">
                <color rgba="1 1 0 1" />
            </material>
        </collision>
        <inertial>
            <mass value="0.1" />
            <origin xyz="0 0 0" rpy="0 0 0" />
            <inertia ixx="0.03" iyy="0.03" izz="0.03" ixy="0.0" ixz="0.0" iyz="0.0" />
        </inertial>
    </link>
    <link name="irb4400_link_5">
        <visual>
            <origin rpy="0 0 0" xyz="0 0 0" />
            <geometry>
                <mesh filename="package://abb_irb4400_45_support/meshes/irb4400_45_196/visual/link_5.stl" />
            </geometry>
            <material name="">
                <color rgba="0.7372549 0.3490196 0.1607843 1" />
            </material>
        </visual>
        <collision>
            <origin rpy="0 0 0" xyz="0 0 0" />
            <geometry>
                <mesh filename="package://abb_irb4400_45_support/meshes/irb4400_45_196/collision/link_5.stl" />
            </geometry>
            <material name="">
                <color rgba="1 1 0 1" />
            </material>
        </collision>
        <inertial>
            <mass value="0.1" />
            <origin xyz="0 0 0" rpy="0 0 0" />
            <inertia ixx="0.03" iyy="0.03" izz="0.03" ixy="0.0" ixz="0.0" iyz="0.0" />
        </inertial>
    </link>
    <link name="irb4400_link_6">
        <visual>
            <origin rpy="0 0 0" xyz="0 0 0" />
            <geometry>
                <mesh filename="package://abb_irb4400_45_support/meshes/irb4400_45_196/visual/link_6.stl" />
            </geometry>
            <material name="">
                <color rgba="0.1882353 0.1960784 0.2039216 1" />
            </material>
        </visual>
        <collision>
            <origin rpy="0 0 0" xyz="0 0 0" />
            <geometry>
                <mesh filename="package://abb_irb4400_45_support/meshes/irb4400_45_196/collision/link_6.stl" />
            </geometry>
            <material name="">
                <color rgba="1 1 0 1" />
            </material>
        </collision>
        <inertial>
            <mass value="0.1" />
            <origin xyz="0 0 0" rpy="0 0 0" />
            <inertia ixx="0.03" iyy="0.03" izz="0.03" ixy="0.0" ixz="0.0" iyz="0.0" />
        </inertial>
    </link>
    <link name="irb4400_tool0" />
    <!-- end of link list -->
    <!-- joint list -->
    <joint name="irb4400_joint_1" type="revolute">
        <origin rpy="0 0 0" xyz="0 0 0" />
        <parent link="irb4400_base_link" />
        <child link="irb4400_link_1" />
        <axis xyz="0 0 1" />
        <limit effort="0" lower="-2.87979" upper="2.87979" velocity="2.618" />
    </joint>
    <joint name="irb4400_joint_2" type="revolute">
        <origin rpy="0 0 0" xyz="0.2 0 0.68" />
        <parent link="irb4400_link_1" />
        <child link="irb4400_link_2" />
        <axis xyz="0 1 0" />
        <limit effort="0" lower="-1.2217" upper="1.658" velocity="2.0944" />
    </joint>
    <joint name="irb4400_joint_3" type="revolute">
        <origin rpy="0 0 0" xyz="0 0 0.89" />
        <parent link="irb4400_link_2" />
        <child link="irb4400_link_3" />
        <axis xyz="0 1 0" />
        <limit effort="0" lower="-1.0472" upper="1.1345" velocity="2.0944" />
    </joint>
    <joint name="irb4400_joint_4" type="revolute">
        <origin rpy="0 0 0" xyz="0.88 0 0.15" />
        <parent link="irb4400_link_3" />
        <child link="irb4400_link_4" />
        <axis xyz="1 0 0" />
        <limit effort="0" lower="-3.49" upper="3.49" velocity="3.927" />
    </joint>
    <joint name="irb4400_joint_5" type="revolute">
        <origin rpy="0 0 0" xyz="0 0 0" />
        <parent link="irb4400_link_4" />
        <child link="irb4400_link_5" />
        <axis xyz="0 1 0" />
        <limit effort="0" lower="-2.0944" upper="2.0944" velocity="4.3633" />
    </joint>
    <joint name="irb4400_joint_6" type="revolute">
        <origin rpy="0 0 0" xyz="0 0 0" />
        <parent link="irb4400_link_5" />
        <child link="irb4400_link_6" />
        <axis xyz="1 0 0" />
        <limit effort="0" lower="-6.9813" upper="6.9813" velocity="5.7596" />
    </joint>
    <joint name="irb4400_joint_6-tool0" type="fixed">
        <parent link="irb4400_link_6" />
        <child link="irb4400_tool0" />
        <origin rpy="0 0 0" xyz="0.14 0 0" />
    </joint>
    <!-- end of joint list -->
    <!-- ROS base_link to ABB World Coordinates transform -->
    <link name="irb4400_base" />
    <joint name="irb4400_base_link-base" type="fixed">
        <origin rpy="0 0 0" xyz="0 0 0" />
        <parent link="irb4400_base_link" />
        <child link="irb4400_base" />
    </joint>
    <link name="world" />
    <joint name="irb6640_world_joint" type="fixed">
        <origin rpy="0 0 0" xyz="0 0 0" />
        <parent link="world" />
        <child link="irb6640_track" />
    </joint>
    <joint name="irb4400_world_joint" type="fixed">
        <origin rpy="0 0 3.141592653589793" xyz="8.226 0 -0.382" />
        <parent link="world" />
        <child link="irb4400_base_link" />
    </joint>
    <transmission name="trans_irb6640_joint_1">
        <type>transmission_interface/SimpleTransmission</type>
        <joint name="irb6640_joint_1">
            <hardwareInterface>hardware_interface/EffortJointInterface</hardwareInterface>
        </joint>
        <actuator name="irb6640_joint_1_motor">
            <hardwareInterface>hardware_interface/EffortJointInterface</hardwareInterface>
            <mechanicalReduction>1</mechanicalReduction>
        </actuator>
    </transmission>
    <transmission name="trans_irb6640_joint_2">
        <type>transmission_interface/SimpleTransmission</type>
        <joint name="irb6640_joint_2">
            <hardwareInterface>hardware_interface/EffortJointInterface</hardwareInterface>
        </joint>
        <actuator name="irb6640_joint_2_motor">
            <hardwareInterface>hardware_interface/EffortJointInterface</hardwareInterface>
            <mechanicalReduction>1</mechanicalReduction>
        </actuator>
    </transmission>
    <transmission name="trans_irb6640_joint_3">
        <type>transmission_interface/SimpleTransmission</type>
        <joint name="irb6640_joint_3">
            <hardwareInterface>hardware_interface/EffortJointInterface</hardwareInterface>
        </joint>
        <actuator name="irb6640_joint_3_motor">
            <hardwareInterface>hardware_interface/EffortJointInterface</hardwareInterface>
            <mechanicalReduction>1</mechanicalReduction>
        </actuator>
    </transmission>
    <transmission name="trans_irb6640_joint_4">
        <type>transmission_interface/SimpleTransmission</type>
        <joint name="irb6640_joint_4">
            <hardwareInterface>hardware_interface/EffortJointInterface</hardwareInterface>
        </joint>
        <actuator name="irb6640_joint_4_motor">
            <hardwareInterface>hardware_interface/EffortJointInterface</hardwareInterface>
            <mechanicalReduction>1</mechanicalReduction>
        </actuator>
    </transmission>
    <transmission name="trans_irb6640_joint_5">
        <type>transmission_interface/SimpleTransmission</type>
        <joint name="irb6640_joint_5">
            <hardwareInterface>hardware_interface/EffortJointInterface</hardwareInterface>
        </joint>
        <actuator name="irb6640_joint_5_motor">
            <hardwareInterface>hardware_interface/EffortJointInterface</hardwareInterface>
            <mechanicalReduction>1</mechanicalReduction>
        </actuator>
    </transmission>
    <transmission name="trans_irb6640_joint_6">
        <type>transmission_interface/SimpleTransmission</type>
        <joint name="irb6640_joint_6">
            <hardwareInterface>hardware_interface/EffortJointInterface</hardwareInterface>
        </joint>
        <actuator name="irb6640_joint_6_motor">
            <hardwareInterface>hardware_interface/EffortJointInterface</hardwareInterface>
            <mechanicalReduction>1</mechanicalReduction>
        </actuator>
    </transmission>
    <transmission name="trans_irb6640_joint_cylinder">
        <type>transmission_interface/SimpleTransmission</type>
        <joint name="irb6640_joint_cylinder">
            <hardwareInterface>hardware_interface/EffortJointInterface</hardwareInterface>
        </joint>
        <actuator name="irb6640_joint_cylinder_motor">
            <hardwareInterface>hardware_interface/EffortJointInterface</hardwareInterface>
            <mechanicalReduction>1</mechanicalReduction>
        </actuator>
    </transmission>
    <transmission name="trans_irb6640_joint_piston">
        <type>transmission_interface/SimpleTransmission</type>
        <joint name="irb6640_joint_piston">
            <hardwareInterface>hardware_interface/EffortJointInterface</hardwareInterface>
        </joint>
        <actuator name="irb6640_joint_piston_motor">
            <hardwareInterface>hardware_interface/EffortJointInterface</hardwareInterface>
            <mechanicalReduction>1</mechanicalReduction>
        </actuator>
    </transmission>
    <transmission name="trans_irb6640_track_1">
        <type>transmission_interface/SimpleTransmission</type>
        <joint name="irb6640_track_1">
            <hardwareInterface>hardware_interface/EffortJointInterface</hardwareInterface>
        </joint>
        <actuator name="irb6640_track_1_motor">
            <hardwareInterface>hardware_interface/EffortJointInterface</hardwareInterface>
            <mechanicalReduction>1</mechanicalReduction>
        </actuator>
    </transmission>
    <transmission name="trans_irb4400_joint_1">
        <type>transmission_interface/SimpleTransmission</type>
        <joint name="irb4400_joint_1">
            <hardwareInterface>hardware_interface/EffortJointInterface</hardwareInterface>
        </joint>
        <actuator name="irb4400_joint_1_motor">
            <hardwareInterface>hardware_interface/EffortJointInterface</hardwareInterface>
            <mechanicalReduction>1</mechanicalReduction>
        </actuator>
    </transmission>
    <transmission name="trans_irb4400_joint_2">
        <type>transmission_interface/SimpleTransmission</type>
        <joint name="irb4400_joint_2">
            <hardwareInterface>hardware_interface/EffortJointInterface</hardwareInterface>
        </joint>
        <actuator name="irb4400_joint_2_motor">
            <hardwareInterface>hardware_interface/EffortJointInterface</hardwareInterface>
            <mechanicalReduction>1</mechanicalReduction>
        </actuator>
    </transmission>
    <transmission name="trans_irb4400_joint_3">
        <type>transmission_interface/SimpleTransmission</type>
        <joint name="irb4400_joint_3">
            <hardwareInterface>hardware_interface/EffortJointInterface</hardwareInterface>
        </joint>
        <actuator name="irb4400_joint_3_motor">
            <hardwareInterface>hardware_interface/EffortJointInterface</hardwareInterface>
            <mechanicalReduction>1</mechanicalReduction>
        </actuator>
    </transmission>
    <transmission name="trans_irb4400_joint_4">
        <type>transmission_interface/SimpleTransmission</type>
        <joint name="irb4400_joint_4">
            <hardwareInterface>hardware_interface/EffortJointInterface</hardwareInterface>
        </joint>
        <actuator name="irb4400_joint_4_motor">
            <hardwareInterface>hardware_interface/EffortJointInterface</hardwareInterface>
            <mechanicalReduction>1</mechanicalReduction>
        </actuator>
    </transmission>
    <transmission name="trans_irb4400_joint_5">
        <type>transmission_interface/SimpleTransmission</type>
        <joint name="irb4400_joint_5">
            <hardwareInterface>hardware_interface/EffortJointInterface</hardwareInterface>
        </joint>
        <actuator name="irb4400_joint_5_motor">
            <hardwareInterface>hardware_interface/EffortJointInterface</hardwareInterface>
            <mechanicalReduction>1</mechanicalReduction>
        </actuator>
    </transmission>
    <transmission name="trans_irb4400_joint_6">
        <type>transmission_interface/SimpleTransmission</type>
        <joint name="irb4400_joint_6">
            <hardwareInterface>hardware_interface/EffortJointInterface</hardwareInterface>
        </joint>
        <actuator name="irb4400_joint_6_motor">
            <hardwareInterface>hardware_interface/EffortJointInterface</hardwareInterface>
            <mechanicalReduction>1</mechanicalReduction>
        </actuator>
    </transmission>
    <gazebo>
        <plugin name="gazebo_ros_control">
            <robotNamespace>/</robotNamespace>
        </plugin>
    </gazebo>
</robot>

